<mujoco>
    <compiler autolimits="true"></compiler>
    <asset>
        <texture name="grid" type="2d" builtin="checker" width="512" height="512" rgb1=".1 .2 .3" rgb2=".2 .3 .4"></texture>
        <material name="grid" texture="grid" texrepeat="1 1" texuniform="true" reflectance=".2"></material>
        <mesh name="chasis" scale=".01 .006 .0015" vertex=" 9   2   0 -10  10  10 9  -2   0 10  3  -10 10 -3  -10 -8   10 -10 -10 -10  10 -8  -10 -10 -5   0   20"></mesh>
    </asset>
    <default>
        <joint damping=".03" actuatorfrcrange="-0.5 0.5"></joint>
        <default class="wheel">
            <geom type="cylinder" size=".03 .01" rgba=".5 .5 1 1"></geom>
        </default>
        <default class="decor">
            <site type="box" rgba=".5 1 .5 1"></site>
        </default>
    </default>
    <worldbody>
        <geom type="plane" size="3 3 .01" material="grid"></geom>
        <body name="car" pos="0 0 .03">
            <freejoint></freejoint>
            <light name="top light" pos="0 0 2" mode="trackcom" diffuse=".4 .4 .4"></light>
            <geom name="chasis" type="mesh" mesh="chasis"></geom>
            <geom name="front wheel" pos=".08 0 -.015" type="sphere" size=".015" condim="1" priority="1"></geom>
            <light name="front light" pos=".1 0 .02" dir="2 0 -1" diffuse="1 1 1"></light>
            <body name="left_wheel" pos="-0.07 0.06 0" zaxis="0 1 0">
                <joint name="left_"></joint>
                <geom class="wheel"></geom>
                <site class="decor" size=".006 .025 .012"></site>
                <site class="decor" size=".025 .006 .012"></site>
            </body>
            <body name="right_wheel" pos="-0.07 -0.06 0" zaxis="0 1 0">
                <joint name="right_"></joint>
                <geom class="wheel"></geom>
                <site class="decor" size=".006 .025 .012"></site>
                <site class="decor" size=".025 .006 .012"></site>
            </body>
        </body>
    </worldbody>
    <tendon>
        <fixed name="forward_">
            <joint joint="left" coef="0.5"></joint>
            <joint joint="right" coef="0.5"></joint>
        </fixed>
        <fixed name="turn_">
            <joint joint="left" coef="-0.5"></joint>
            <joint joint="right" coef="0.5"></joint>
        </fixed>
    </tendon>
    <actuator>
        <motor name="forward" tendon="forward" ctrlrange="-1 1"></motor>
        <motor name="turn" tendon="turn" ctrlrange="-1 1"></motor>
    </actuator>
    <sensor>
        <jointactuatorfrc name="right" joint="right"></jointactuatorfrc>
        <jointactuatorfrc name="left" joint="left"></jointactuatorfrc>
    </sensor>
</mujoco>